INFO:Datapulse.imageGen:Importing imageGen
WARNING:discord.client:PyNaCl is not installed, voice will NOT be supported
[2024-06-10 15:08:10] [INFO    ] discord.client: logging in using static token
INFO:discord.client:logging in using static token
[2024-06-10 15:08:11] [INFO    ] discord.gateway: Shard ID None has connected to Gateway (Session ID: a47841790c626949c1a52576105a5411).
INFO:discord.gateway:Shard ID None has connected to Gateway (Session ID: a47841790c626949c1a52576105a5411).
INFO:db:Database tables created
INFO:Datapulse.imageGen:Starting a Generator instance for Host localhost:8188
[2024-06-10 15:08:23] [ERROR   ] discord.app_commands.tree: Ignoring exception in command 'imagine'
Traceback (most recent call last):
  File "/home/alex/DataPusle_bot/venv/lib/python3.10/site-packages/discord/app_commands/commands.py", line 828, in _do_call
    return await self._callback(interaction, **params)  # type: ignore
  File "/home/alex/DataPusle_bot/bot.py", line 470, in imagine
    await generate_images(
  File "/home/alex/DataPusle_bot/imageGen.py", line 604, in generate_images
    images = await generator.get_images(workflow)
  File "/home/alex/DataPusle_bot/imageGen.py", line 345, in get_images
    prompt_id = queue_prompt(prompt, self.client_id, host=self.host)["prompt_id"]
  File "/home/alex/DataPusle_bot/imageGen.py", line 76, in queue_prompt
    return json.loads(urllib.request.urlopen(req).read())
  File "/usr/lib/python3.10/urllib/request.py", line 216, in urlopen
    return opener.open(url, data, timeout)
  File "/usr/lib/python3.10/urllib/request.py", line 525, in open
    response = meth(req, response)
  File "/usr/lib/python3.10/urllib/request.py", line 634, in http_response
    response = self.parent.error(
  File "/usr/lib/python3.10/urllib/request.py", line 563, in error
    return self._call_chain(*args)
  File "/usr/lib/python3.10/urllib/request.py", line 496, in _call_chain
    result = func(*args)
  File "/usr/lib/python3.10/urllib/request.py", line 643, in http_error_default
    raise HTTPError(req.full_url, code, msg, hdrs, fp)
urllib.error.HTTPError: HTTP Error 400: Bad Request

The above exception was the direct cause of the following exception:

Traceback (most recent call last):
  File "/home/alex/DataPusle_bot/venv/lib/python3.10/site-packages/discord/app_commands/tree.py", line 1248, in _call
    await command._invoke_with_namespace(interaction, namespace)
  File "/home/alex/DataPusle_bot/venv/lib/python3.10/site-packages/discord/app_commands/commands.py", line 853, in _invoke_with_namespace
    return await self._do_call(interaction, transformed_values)
  File "/home/alex/DataPusle_bot/venv/lib/python3.10/site-packages/discord/app_commands/commands.py", line 846, in _do_call
    raise CommandInvokeError(self, e) from e
discord.app_commands.errors.CommandInvokeError: Command 'imagine' raised an exception: HTTPError: HTTP Error 400: Bad Request
ERROR:discord.app_commands.tree:Ignoring exception in command 'imagine'
Traceback (most recent call last):
  File "/home/alex/DataPusle_bot/venv/lib/python3.10/site-packages/discord/app_commands/commands.py", line 828, in _do_call
    return await self._callback(interaction, **params)  # type: ignore
  File "/home/alex/DataPusle_bot/bot.py", line 470, in imagine
    await generate_images(
  File "/home/alex/DataPusle_bot/imageGen.py", line 604, in generate_images
    images = await generator.get_images(workflow)
  File "/home/alex/DataPusle_bot/imageGen.py", line 345, in get_images
    prompt_id = queue_prompt(prompt, self.client_id, host=self.host)["prompt_id"]
  File "/home/alex/DataPusle_bot/imageGen.py", line 76, in queue_prompt
    return json.loads(urllib.request.urlopen(req).read())
  File "/usr/lib/python3.10/urllib/request.py", line 216, in urlopen
    return opener.open(url, data, timeout)
  File "/usr/lib/python3.10/urllib/request.py", line 525, in open
    response = meth(req, response)
  File "/usr/lib/python3.10/urllib/request.py", line 634, in http_response
    response = self.parent.error(
  File "/usr/lib/python3.10/urllib/request.py", line 563, in error
    return self._call_chain(*args)
  File "/usr/lib/python3.10/urllib/request.py", line 496, in _call_chain
    result = func(*args)
  File "/usr/lib/python3.10/urllib/request.py", line 643, in http_error_default
    raise HTTPError(req.full_url, code, msg, hdrs, fp)
urllib.error.HTTPError: HTTP Error 400: Bad Request

The above exception was the direct cause of the following exception:

Traceback (most recent call last):
  File "/home/alex/DataPusle_bot/venv/lib/python3.10/site-packages/discord/app_commands/tree.py", line 1248, in _call
    await command._invoke_with_namespace(interaction, namespace)
  File "/home/alex/DataPusle_bot/venv/lib/python3.10/site-packages/discord/app_commands/commands.py", line 853, in _invoke_with_namespace
    return await self._do_call(interaction, transformed_values)
  File "/home/alex/DataPusle_bot/venv/lib/python3.10/site-packages/discord/app_commands/commands.py", line 846, in _do_call
    raise CommandInvokeError(self, e) from e
discord.app_commands.errors.CommandInvokeError: Command 'imagine' raised an exception: HTTPError: HTTP Error 400: Bad Request
